<?xml version="1.0"?>

<robot name="scout_mini" xmlns:xacro="http://ros.org/wiki/xacro">
    <!-- Vehicle Geometries -->
    
    <!-- Base link -->
    <link name="base_link">
        <visual>
            <origin xyz="0 0 0" rpy="1.57 0 -1.57" />
            <geometry>
                <mesh
                    filename="package://scout_description/meshes/scout_mini_base_link.dae" />
            </geometry>
        </visual>
        <collision>
            <origin xyz="0 0 0" rpy="1.57 0 -1.57" />
            <geometry>
                <mesh
                    filename="package://scout_description/meshes/scout_mini_base_link.dae" />
            </geometry>
        </collision>
    </link>

    <link
        name="inertial_link">
        <inertial>
            <mass value="132.3898489950015" />
            <origin xyz=" 0 0 0" />
            <inertia ixx="0.185196122711036" ixy="4.30144213829512E-08" ixz="5.81037523686401E-08"
                iyy="0.364893736238929" iyz="-0.000386720198091934" izz="0.223868521722778" />
        </inertial>
    </link>

    <joint
        name="inertial_joint" type="fixed">
        <origin xyz="0 0 0" rpy="0 0 0" />
        <parent link="base_link" />
        <child link="inertial_link" />
    </joint>

    <!-- Scout wheel -->
    <link
        name="front_right_wheel_link">
        <inertial>
            <mass value="3" />
            <origin xyz="0 0 0" />
            <inertia ixx="0.7171" ixy="0" ixz="0" iyy="0.7171" iyz="0" izz="0.1361" />
        </inertial>
        <visual>
            <origin xyz="0 0 0" rpy="0 0 0" />
            <geometry>
                <mesh filename="package://scout_description/meshes/wheel.dae" />
            </geometry>
        </visual>
        <collision>
            <origin xyz="0 0 0" rpy="0 0 0" />
            <geometry>
                <mesh filename="package://scout_description/meshes/wheel.dae" />
            </geometry>
        </collision>
    </link>

    <joint
        name="front_right_wheel" type="continuous">
        <origin rpy="1.57 0 0" xyz="0.2319755 -0.2082515 -0.099998" />
        <parent link="base_link" />
        <child link="front_right_wheel_link" />
        <axis xyz="0 0 -1" rpy="0 0 0" />
    </joint>

    <link name="front_left_wheel_link">
        <inertial>
            <mass value="3" />
            <origin xyz="0 0 0" />
            <inertia ixx="0.7171" ixy="0" ixz="0" iyy="0.7171" iyz="0" izz="0.1361" />
        </inertial>
        <visual>
            <origin xyz="0 0 0" rpy="0 0 0" />
            <geometry>
                <mesh filename="package://scout_description/meshes/wheel.dae" />
            </geometry>
        </visual>
        <collision>
            <origin xyz="0 0 0" rpy="0 0 0" />
            <geometry>
                <mesh filename="package://scout_description/meshes/wheel.dae" />
            </geometry>
        </collision>
    </link>

    <joint
        name="front_left_wheel" type="continuous">
        <origin rpy="-1.57 0 0" xyz="0.2319755 0.2082515 -0.100998" />
        <parent link="base_link" />
        <child link="front_left_wheel_link" />
        <axis xyz="0 0 1" rpy="0 0 0" />
    </joint>

    <link name="rear_right_wheel_link">
        <inertial>
            <mass value="3" />
            <origin xyz="0 0 0" />
            <inertia ixx="0.7171" ixy="0" ixz="0" iyy="0.7171" iyz="0" izz="0.1361" />
        </inertial>
        <visual>
            <origin xyz="0 0 0" rpy="0 0 0" />
            <geometry>
                <mesh filename="package://scout_description/meshes/wheel.dae" />
            </geometry>
        </visual>
        <collision>
            <origin xyz="0 0 0" rpy="0 0 0" />
            <geometry>
                <mesh filename="package://scout_description/meshes/wheel.dae" />
            </geometry>
        </collision>
    </link>

    <joint
        name="rear_right_wheel" type="continuous">
        <origin rpy="1.57 0 0" xyz="-0.2319755 -0.2082515 -0.099998" />
        <parent link="base_link" />
        <child link="rear_right_wheel_link" />
        <axis xyz="0 0 -1" rpy="0 0 0" />
    </joint>

    <link name="rear_left_wheel_link">
        <inertial>
            <mass value="3" />
            <origin xyz="0 0 0" />
            <inertia ixx="0.7171" ixy="0" ixz="0" iyy="0.7171" iyz="0" izz="0.1361" />
        </inertial>
        <visual>
            <origin xyz="0 0 0" rpy="0 0 0" />
            <geometry>
                <mesh filename="package://scout_description/meshes/wheel.dae" />
            </geometry>
        </visual>
        <collision>
            <origin xyz="0 0 0" rpy="0 0 0" />
            <geometry>
                <mesh filename="package://scout_description/meshes/wheel.dae" />
            </geometry>
        </collision>
    </link>

    <joint
        name="rear_left_wheel" type="continuous">
        <origin rpy="-1.57 0 0" xyz="-0.2319755 0.2082515 -0.100998" />
        <parent link="base_link" />
        <child link="rear_left_wheel_link" />
        <axis xyz="0 0 1" rpy="0 0 0" />
    </joint>

    <!-- Scout gazebo plugin -->
    <gazebo>
        <plugin filename="libignition-gazebo-joint-state-publisher-system.so"
            name="ignition::gazebo::systems::JointStatePublisher">
            <topic>joint_states</topic>

            <update_rate>50</update_rate>

            <joint_name>front_right_wheel</joint_name>
            <joint_name>front_left_wheel</joint_name>
            <joint_name>rear_right_wheel</joint_name>
            <joint_name>rear_left_wheel</joint_name>
        </plugin>

        <plugin
            filename="libignition-gazebo-diff-drive-system.so"
            name="ignition::gazebo::systems::DiffDrive">

            <left_joint>front_left_wheel</left_joint>
            <right_joint>front_right_wheel</right_joint>
            <left_joint>rear_left_wheel</left_joint>
            <right_joint>rear_right_wheel</right_joint>

            <wheel_separation>0.490</wheel_separation>
            <wheel_radius>0.160</wheel_radius>

            <!-- limits -->
            <max_wheel_torque>20</max_wheel_torque>
            <max_linear_acceleration>1.0</max_linear_acceleration>

            <!-- Plugin settings -->
            <topic>cmd_vel</topic>
            <odom_topic>odom</odom_topic>
            <tf_topic>tf</tf_topic>
            <odom_publish_frequency>50</odom_publish_frequency>

            <frame_id>odom</frame_id>
            <child_frame_id>base_link</child_frame_id>
        </plugin>
    </gazebo>
    
    <joint name="lidar_joint" type="fixed">
        <parent link="base_link"/>
        <child link="lidar_link"/>
        <origin xyz="0.2 0 0.15" rpy="0 0 0"/>
    </joint>

    <link name="lidar_link">
        <visual>
            <geometry> <cylinder radius="0.035" length="0.04"/> </geometry>
            <material name="black"> <color rgba="0.0 0.0 0.0 1.0"/> </material>
        </visual>
        <collision>
            <geometry> <cylinder radius="0.035" length="0.04"/> </geometry>
        </collision>
        <inertial>
            <mass value="0.1"/>
            <inertia ixx="0.001" ixy="0" ixz="0" iyy="0.001" iyz="0" izz="0.001"/>
        </inertial>
    </link>

    <gazebo reference="lidar_link">
        <sensor name="rplidar" type="gpu_lidar">
            <pose>0 0 0 0 0 0</pose> <always_on>true</always_on>
            <visualize>true</visualize>
            <update_rate>10</update_rate>
            <topic>scan</topic> <lidar>
                <scan>
                    <horizontal>
                        <samples>360</samples>
                        <resolution>1</resolution>
                        <min_angle>-3.14</min_angle>
                        <max_angle>3.14</max_angle>
                    </horizontal>
                </scan>
                <range>
                    <min>0.15</min>
                    <max>12.0</max>
                    <resolution>0.01</resolution>
                </range>
                <noise>
                    <type>gaussian</type>
                    <mean>0.0</mean>
                    <stddev>0.01</stddev>
                </noise>
            </lidar>
        </sensor>
    </gazebo>


        <gazebo reference="base_link">
        <sensor name="rtk_gps" type="navsat">
            <always_on>1</always_on>
            <update_rate>10.0</update_rate> <topic>gps/fix</topic>            
            <ignition_frame_id>base_link</ignition_frame_id>
            <navsat>
                <position_sensing>
                    <horizontal>
                        <noise type="gaussian">
                            <mean>0.0</mean>
                            <stddev>0.0000002</stddev> </noise>
                    </horizontal>
                    <vertical>
                        <noise type="gaussian">
                            <mean>0.0</mean>
                            <stddev>0.01</stddev>
                        </noise>
                    </vertical>
                </position_sensing>
            </navsat>
        </sensor>
    </gazebo>
    
</robot>